Workbook
Name Slicer_Buyer_Segment1: #N/A
Name Slicer_Country1: #N/A
Name Slicer_Product_Name: #N/A
Name Slicer_Row_Labels: #N/A
Name Slicer_Year: #N/A

Sheet PVTB (2)
A1: KPI SCORE
A2: Sum of Revenue | B2: Sum of Gross Profit | C2: Sum of Qty Sold | D2: Count of Order Code | H2: Sum of Net Profit | I2: Sum of Revenue | J2: Sum of Operating Profit
A3: 1.4624349e+08 | B3: 48901720 | C3: 1125788 | D3: 700 | H3: 44361025 | I3: 1.8582563e+08 | J3: 32406071
A6: PERIODE REVENUE
A7: Row Labels | B7: Sum of Revenue | D7: Row Labels | E7: Sum of Revenue | H7: Row Labels | I7: Sum of Net Profit
A8: 1 | B8: 9010492.2 | D8: 2013 | E8: 34187987 | H8: 2013 | I8: 6432964.3
A9: 2 | B9: 8273702.7 | D9: 2014 | E9: 1.1205551e+08 | H9: 2014 | I9: 21275937
A10: 3 | B10: 6761197.3 | D10: Grand Total | E10: 1.4624349e+08 | H10: 2015 | I10: 16652123
A11: 4 | B11: 9534182.6 | H11: Grand Total | I11: 44361025
A12: 5 | B12: 7175087.1
A13: 6 | B13: 14262981 | H13: Row Labels | I13: Sum of Revenue | J13: Sum of Net Profit
A14: 7 | B14: 8735012.1 | H14: 2013 | I14: 34187987 | J14: 6432964.3
A15: 8 | B15: 8377662.5 | H15: 2014 | I15: 1.1205551e+08 | J15: 21275937
A16: 9 | B16: 14013055 | H16: 2015 | I16: 39582132 | J16: 16652123
A17: 10 | B17: 25760669 | H17: Grand Total | I17: 1.8582563e+08 | J17: 44361025
A18: 11 | B18: 15089559
A19: 12 | B19: 19249893 | H19: Row Labels | I19: Sum of Gross Profit | J19: Sum of Operating Profit | K19: Sum of Net Profit
A20: Grand Total | B20: 1.4624349e+08 | H20: 2013 | I20: 11219785 | J20: 7470440.3 | K20: 6432964.3
H21: 2014 | I21: 37681934 | J21: 24935630 | K21: 21275937
A22: REVENUE BY COUNTRY | D22: MAPS CHART | H22: Grand Total | I22: 48901720 | J22: 32406071 | K22: 27708902
A23: Row Labels | B23: Sum of Revenue | D23: Row Labels | E23: Sum of Revenue
A24: United States of America | B24: 31580640 | D24: =IF(A24="","",A24) -> United States of America | E24: =B24 -> 31580640 | H24: Row Labels | I24: Sum of G&A Cost | J24: Sum of Handling Cost | K24: Sum of Tax
A25: Canada | B25: 31180464 | D25: =IF(A25="","",A25) -> Canada | E25: =B25 -> 31180464 | H25: 2013 | I25: 854023 | J25: 2895322 | K25: 1037476
A26: France | B26: 30964625 | D26: =IF(A26="","",A26) -> France | E26: =B26 -> 30964625 | H26: 2014 | I26: 3532853 | J26: 9213451 | K26: 3659693
A27: Germany | B27: 27676846 | D27: =IF(A27="","",A27) -> Germany | E27: =B27 -> 27676846 | H27: Grand Total | I27: 4386876 | J27: 12108773 | K27: 4697169
A28: Mexico | B28: 24840919 | D28: =IF(A28="","",A28) -> Mexico | E28: =B28 -> 24840919
A29: Grand Total | B29: 1.4624349e+08 | H29: Row Labels | I29: Sum of G&A Cost | J29: Sum of Gross Profit | K29: Sum of Handling Cost | L29: Sum of Net Profit | M29: Sum of Tax
H30: 2013 | I30: 854023 | J30: 11219785 | K30: 2895322 | L30: 6432964.3 | M30: 1037476
A31: Row Labels | B31: Sum of Gross Profit | D31: Row Labels | E31: Sum of Qty Sold | H31: 2014 | I31: 3532853 | J31: 37681934 | K31: 9213451 | L31: 21275937 | M31: 3659693
A32: Channel Partners | B32: 7764769.9 | D32: Channel Partners | E32: 161261 | H32: Grand Total | I32: 4386876 | J32: 48901720 | K32: 12108773 | L32: 27708902 | M32: 4697169
A33: Enterprise | B33: 7407767.4 | D33: Enterprise | E33: 168549
A34: Government | B34: 20789147 | D34: Government | E34: 470665
A35: Midmarket | B35: 6431372.4 | D35: Midmarket | E35: 172176
A36: Small Business | B36: 6508662.5 | D36: Small Business | E36: 153137
A37: Grand Total | B37: 48901720 | D37: Grand Total | E37: 1125788
A39: Row Labels | B39: Sum of Revenue | D39: Row Labels | E39: Sum of Gross Profit
A40: Amarilla | B40: 54359193 | D40: Amarilla | E40: 23296793
A41: VTT | B41: 50633692 | D41: Velo | E41: 9745371.9
A42: Velo | B42: 29236132 | D42: VTT | E42: 8438941.9
A43: Paseo | B43: 6764705.5 | D43: Paseo | E43: 3382345.5
...

Sheet Dashboard (2)
D4: FINANCIAL & SALES PERFORMANCE DASHBOARD
D5: Final Project by B4 Group

Sheet Dashboard
D4: FINANCIAL & SALES PERFORMANCE DASHBOARD
D5: Final Project by B4 Group

Sheet PVTB
A1: KPI SCORE
A2: Sum of Revenue | B2: Sum of Gross Profit | C2: Sum of Qty Sold | D2: Count of Order Code | H2: Sum of Net Profit | I2: Sum of Revenue | J2: Sum of Operating Profit
A3: 1.4624349e+08 | B3: 48901720 | C3: 1125788 | D3: 700 | H3: 44361025 | I3: 1.8582563e+08 | J3: 32406071
A6: PERIODE REVENUE
A7: Row Labels | B7: Sum of Revenue | D7: Row Labels | E7: Sum of Revenue | H7: Row Labels | I7: Sum of Net Profit
A8: 1 | B8: 9010492.2 | D8: 2013 | E8: 34187987 | H8: 2013 | I8: 6432964.3
A9: 2 | B9: 8273702.7 | D9: 2014 | E9: 1.1205551e+08 | H9: 2014 | I9: 21275937
A10: 3 | B10: 6761197.3 | D10: Grand Total | E10: 1.4624349e+08 | H10: 2015 | I10: 16652123
A11: 4 | B11: 9534182.6 | H11: Grand Total | I11: 44361025
A12: 5 | B12: 7175087.1 | E12: =E9-E8 -> 77867519
A13: 6 | B13: 14262981 | E13: 77867519 | H13: Row Labels | I13: Sum of Revenue | J13: Sum of Net Profit
A14: 7 | B14: 8735012.1 | H14: 2013 | I14: 34187987 | J14: 6432964.3
A15: 8 | B15: 8377662.5 | H15: 2014 | I15: 1.1205551e+08 | J15: 21275937
A16: 9 | B16: 14013055 | H16: 2015 | I16: 39582132 | J16: 16652123
A17: 10 | B17: 25760669 | H17: Grand Total | I17: 1.8582563e+08 | J17: 44361025
A18: 11 | B18: 15089559
A19: 12 | B19: 19249893 | H19: Row Labels | I19: Sum of Gross Profit | J19: Sum of Operating Profit | K19: Sum of Net Profit
A20: Grand Total | B20: 1.4624349e+08 | H20: 2013 | I20: 11219785 | J20: 7470440.3 | K20: 6432964.3
H21: 2014 | I21: 37681934 | J21: 24935630 | K21: 21275937
A22: REVENUE BY COUNTRY | E22: MAPS CHART | H22: Grand Total | I22: 48901720 | J22: 32406071 | K22: 27708902
A23: Row Labels | B23: Sum of Revenue | C23: Sum of Gross Profit | E23: Row Labels | F23: Sum of Revenue
A24: Mexico | B24: 24840919 | C24: 8571407 | E24: =IF(A24="","",A24) -> Mexico | F24: =B24 -> 24840919 | H24: Row Labels | I24: Sum of G&A Cost | J24: Sum of Handling Cost | K24: Sum of Tax
A25: Germany | B25: 27676846 | C25: 9273228.5 | E25: =IF(A25="","",A25) -> Germany | F25: =B25 -> 27676846 | H25: 2013 | I25: 854023 | J25: 2895322 | K25: 1037476
A26: France | B26: 30964625 | C26: 10333275 | E26: =IF(A26="","",A26) -> France | F26: =B26 -> 30964625 | H26: 2014 | I26: 3532853 | J26: 9213451 | K26: 3659693
A27: Canada | B27: 31180464 | C27: 10083200 | E27: =IF(A27="","",A27) -> Canada | F27: =B27 -> 31180464 | H27: Grand Total | I27: 4386876 | J27: 12108773 | K27: 4697169
A28: United States of America | B28: 31580640 | C28: 10640609 | E28: =IF(A28="","",A28) -> United States of America | F28: =B28 -> 31580640
A29: Grand Total | B29: 1.4624349e+08 | C29: 48901720 | H29: Row Labels | I29: Sum of G&A Cost | J29: Sum of Gross Profit | K29: Sum of Handling Cost | L29: Sum of Net Profit | M29: Sum of Tax
H30: 2013 | I30: 854023 | J30: 11219785 | K30: 2895322 | L30: 6432964.3 | M30: 1037476
A31: Row Labels | B31: Sum of Gross Profit | D31: Row Labels | E31: Sum of Qty Sold | H31: 2014 | I31: 3532853 | J31: 37681934 | K31: 9213451 | L31: 21275937 | M31: 3659693
A32: Channel Partners | B32: 7764769.9 | D32: Channel Partners | E32: 161261 | H32: Grand Total | I32: 4386876 | J32: 48901720 | K32: 12108773 | L32: 27708902 | M32: 4697169
A33: Enterprise | B33: 7407767.4 | D33: Enterprise | E33: 168549
A34: Government | B34: 20789147 | D34: Government | E34: 470665
A35: Midmarket | B35: 6431372.4 | D35: Midmarket | E35: 172176
A36: Small Business | B36: 6508662.5 | D36: Small Business | E36: 153137
A37: Grand Total | B37: 48901720 | D37: Grand Total | E37: 1125788
A39: Row Labels | B39: Sum of Revenue | D39: Row Labels | E39: Sum of Gross Profit
A40: Amarilla | B40: 54359193 | D40: Amarilla | E40: 23296793
A41: VTT | B41: 50633692 | D41: Velo | E41: 9745371.9
A42: Velo | B42: 29236132 | D42: VTT | E42: 8438941.9
A43: Paseo | B43: 6764705.5 | D43: Paseo | E43: 3382345.5
...

Sheet Concept
A1: Color
A2: Green | B2: #003300 | C2: #004d00 | D2: #006600 | E2: #009900 | F2: #66cc66 | G2: #ccffcc
D3: #007a33 | E3: #66b3a1 | F3: #b2e0d4 | G3: #e0f7f1
A5: Blue | B5: #003366 | C5: #00509e | D5: #007acc | E5: #66a3ff | F5: #cce0ff | G5: #e1f5fe
B6: #1a237e | C6: #0d47a1 | D6: #3949ab | E6: #5c6bc0 | F6: #9fa8da | G6: #e8eaf6
A8: Warm
B10: #ff5722 | C10: ##ff7043 | D10: #ff8a65 | E10: #ffab91 | F10: #ffe0b2 | G10: #fff2e6
B11: #ff6600 | C11: #ff9933 | D11: #ffab40 | E11: #ffcc66 | F11: #ffe6b3
B12: #cddc39 | C12: #ffcc00 | D12: #ffd54f | E12: #ffdb4d | F12: #ffff99

Sheet Guide
A1: Ketentuan
A2: 1 | B2: Selesaikanlah tahapan berikut ini
A3: - | B3: Buatlah Order Code dengan format sebagai berikut: ORD-(Origin Code)-(Segment Code)-(Order date)
A4: - | B4: Format dari Order date pada Order Code adalah yyyymmdd
A5: - | B5: Contoh | C5: : ORD-GER-GOV-20141201
A6: 2 | B6: Ekstrak informasi Order details menjadi kolom-kolom individu
A7: 3 | B7: Lakukan pemrosesan data dengan melengkapi informasi pada sheet Order raw (lookup dan perhitungan) untuk memperoleh informasi berikut:
A8: - | B8: Total price | C8: : Selling price x qty
A9: - | B9: Revenue | C9: : Total price - discount
A10: - | B10: Gross profit | C10: : Revenue - Manufacturing cost
A11: 4 | B11: Lakukan analisa terhadap data perjualan dari beberapa tahun tersebut
A12: 5 | B12: Lakukan analisa lanjutan untuk melihat bagaimana performa tahunan keuangan perusahaan secara keseluruhan dengan mencari nilai berikut secara garis besar
A13: - | B13: Operating profit | C13: : Gross profit - G&A cost - Handling cost
A14: - | B14: Net profit | C14: : Operating profit - tax
A15: 6 | B15: Dari analisa yang dilakukan, tampilan insight dalam bentuk dashboard dengan minimal terdapat 4 chart dan 1 slicer (gunakan pivot table agar lebih mudah)
A16: 7 | B16: Sajikan data dengan baik dan lakukan presentasi terhadap hasil dari analisa yang dilakukan
A17: 8 | B17: Anda bebas menambahkan parameter lain jika memang diperlukan untuk memperoleh hasil analisa yang diinginkan
A19: Informasi Tambahan
B21: Nama negara | C21: Kode negara
B22: Canada | C22: CND
B23: Germany | C23: GER
B24: France | C24: FRA
B25: Mexico | C25: MXC
B26: United States of America | C26: USA
B28: Nama segmen | C28: Kode segmen
B29: Government | C29: GOV
B30: Midmarket | C30: MDM
B31: Channel Partners | C31: CPR
B32: Enterprise | C32: ENT
B33: Small Business | C33: SMB
A35: Definisi kolom
B37: Nama kolom | C37: Keterangan
B38: Order ID | C38: Nomor order
B39: Order details | C39: Informasi order
B40: Country origin | C40: Negara asal pembeli
B41: Buyer segment | C41: Jenis segmen pembeli
B42: Product name | C42: Nama produk
B43: Qty sold | C43: Jumlah barang terjual
B44: Discount % | C44: Besar diskon yang diberikan
B45: Order date | C45: Tanggal pesanan/order

Sheet Order Raw
A1: Order details | B1: Order Code | C1: Country | D1: Buyer Segment | E1: Product Name | F1: Qty Sold | G1: Discount % | H1: Order Date | I1: Date | J1: Month | K1: Year | L1: Total Price | M1: Revenue | N1: Gross Profit | Q1: Year | R1: G&A Cost | S1: Handling Cost | T1: Tax | U1: Gross Profit | V1: Operating Profit | W1: Net Profit | X1: Revenue
A2: {"type": "buyerDetails", "info": ["origin": "Canada", "segment": "Government", "date": "1", "month": "1", "year": "2014", "units": "1618"]} | B2: =_xlfn.IFS(C2="Canada","CND",C2="Germany","GER",C2="France","FRA",C2="Mexico","MXC",C2="United States of America","USA")&"-"&_xlfn.IFS(D2="Government","GOV",D2="Midmarket","MDM",D2="Channel Partners","CPR",D2="Enterprise","ENT",D2="Small Business","SMB")&"-"&TEXT(H2,"yyyymmdd") -> CND-GOV-20140101 | C2: Canada | D2: Government | E2: Carretera | F2: 1618 | G2: 0 | H2: =DATE(K2,J2,I2) -> 41640 | I2: 1 | J2: 1 | K2: 2014 | L2: =VLOOKUP(E2,Product!$A$1:$C$7,3,0)*'Order Raw'!F2 -> 32360 | M2: =L2-G2 -> 32360 | N2: =M2-(VLOOKUP(E2,Product!$A$1:$C$7,2,0)*F2) -> 27506 | Q2: 2013 | R2: ='Other financials'!C2 -> 854023 | S2: ='Other financials'!C3 -> 2895322 | T2: ='Other financials'!C4 -> 1037476 | U2: =SUMIFS(SalesTable[Gross Profit],SalesTable[Year],Q2) -> 11219785 | V2: =U2-'Other financials'!C2-'Other financials'!C3 -> 7470440.3 | W2: =V2-'Other financials'!C4 -> 6432964.3 | X2: =SUMIFS($M:$M,$K:$K,Q2) -> 34187987
A3: {"type": "buyerDetails", "info": ["origin": "Germany", "segment": "Government", "date": "1", "month": "1", "year": "2014", "units": "1321"]} | B3: =_xlfn.IFS(C3="Canada","CND",C3="Germany","GER",C3="France","FRA",C3="Mexico","MXC",C3="United States of America","USA")&"-"&_xlfn.IFS(D3="Government","GOV",D3="Midmarket","MDM",D3="Channel Partners","CPR",D3="Enterprise","ENT",D3="Small Business","SMB")&"-"&TEXT(H3,"yyyymmdd") -> GER-GOV-20140101 | C3: Germany | D3: Government | E3: Carretera | F3: 1321 | G3: 0 | H3: =DATE(K3,J3,I3) -> 41640 | I3: 1 | J3: 1 | K3: 2014 | L3: =VLOOKUP(E3,Product!$A$1:$C$7,3,0)*'Order Raw'!F3 -> 26420 | M3: =L3-G3 -> 26420 | N3: =M3-(VLOOKUP(E3,Product!$A$1:$C$7,2,0)*F3) -> 22457 | Q3: 2014 | R3: ='Other financials'!C5 -> 3532853 | S3: ='Other financials'!C6 -> 9213451 | T3: ='Other financials'!C7 -> 3659693 | U3: =SUMIFS(SalesTable[Gross Profit],SalesTable[Year],Q3) -> 37681934 | V3: =U3-'Other financials'!C5-'Other financials'!C6 -> 24935630 | W3: =V3-'Other financials'!C7 -> 21275937 | X3: =SUMIFS($M:$M,$K:$K,Q3) -> 1.1205551e+08
A4: {"type": "buyerDetails", "info": ["origin": "France", "segment": "Midmarket", "date": "1", "month": "6", "year": "2014", "units": "2178"]} | B4: =_xlfn.IFS(C4="Canada","CND",C4="Germany","GER",C4="France","FRA",C4="Mexico","MXC",C4="United States of America","USA")&"-"&_xlfn.IFS(D4="Government","GOV",D4="Midmarket","MDM",D4="Channel Partners","CPR",D4="Enterprise","ENT",D4="Small Business","SMB")&"-"&TEXT(H4,"yyyymmdd") -> FRA-MDM-20140601 | C4: France | D4: Midmarket | E4: Carretera | F4: 2178 | G4: 0 | H4: =DATE(K4,J4,I4) -> 41791 | I4: 1 | J4: 6 | K4: 2014 | L4: =VLOOKUP(E4,Product!$A$1:$C$7,3,0)*'Order Raw'!F4 -> 43560 | M4: =L4-G4 -> 43560 | N4: =M4-(VLOOKUP(E4,Product!$A$1:$C$7,2,0)*F4) -> 37026 | Q4: 2015 | R4: 0 | S4: 0 | T4: 0 | U4: 0 | V4: 0 | W4: ='Other financials'!C9 -> 16652123 | X4: ='Other financials'!C8 -> 39582132
A5: {"type": "buyerDetails", "info": ["origin": "Germany", "segment": "Midmarket", "date": "1", "month": "6", "year": "2014", "units": "888"]} | B5: =_xlfn.IFS(C5="Canada","CND",C5="Germany","GER",C5="France","FRA",C5="Mexico","MXC",C5="United States of America","USA")&"-"&_xlfn.IFS(D5="Government","GOV",D5="Midmarket","MDM",D5="Channel Partners","CPR",D5="Enterprise","ENT",D5="Small Business","SMB")&"-"&TEXT(H5,"yyyymmdd") -> GER-MDM-20140601 | C5: Germany | D5: Midmarket | E5: Carretera | F5: 888 | G5: 0 | H5: =DATE(K5,J5,I5) -> 41791 | I5: 1 | J5: 6 | K5: 2014 | L5: =VLOOKUP(E5,Product!$A$1:$C$7,3,0)*'Order Raw'!F5 -> 17760 | M5: =L5-G5 -> 17760 | N5: =M5-(VLOOKUP(E5,Product!$A$1:$C$7,2,0)*F5) -> 15096
A6: {"type": "buyerDetails", "info": ["origin": "Mexico", "segment": "Midmarket", "date": "1", "month": "6", "year": "2014", "units": "2470"]} | B6: =_xlfn.IFS(C6="Canada","CND",C6="Germany","GER",C6="France","FRA",C6="Mexico","MXC",C6="United States of America","USA")&"-"&_xlfn.IFS(D6="Government","GOV",D6="Midmarket","MDM",D6="Channel Partners","CPR",D6="Enterprise","ENT",D6="Small Business","SMB")&"-"&TEXT(H6,"yyyymmdd") -> MXC-MDM-20140601 | C6: Mexico | D6: Midmarket | E6: Carretera | F6: 2470 | G6: 0 | H6: =DATE(K6,J6,I6) -> 41791 | I6: 1 | J6: 6 | K6: 2014 | L6: =VLOOKUP(E6,Product!$A$1:$C$7,3,0)*'Order Raw'!F6 -> 49400 | M6: =L6-G6 -> 49400 | N6: =M6-(VLOOKUP(E6,Product!$A$1:$C$7,2,0)*F6) -> 41990 | Q6: Gross Profit | R6: =_xlfn.FORMULATEXT(U2) -> =SUMIFS(SalesTable[Gross Profit];SalesTable[Year];Q2) | S6: 2013
A7: {"type": "buyerDetails", "info": ["origin": "Germany", "segment": "Government", "date": "1", "month": "12", "year": "2014", "units": "1513"]} | B7: =_xlfn.IFS(C7="Canada","CND",C7="Germany","GER",C7="France","FRA",C7="Mexico","MXC",C7="United States of America","USA")&"-"&_xlfn.IFS(D7="Government","GOV",D7="Midmarket","MDM",D7="Channel Partners","CPR",D7="Enterprise","ENT",D7="Small Business","SMB")&"-"&TEXT(H7,"yyyymmdd") -> GER-GOV-20141201 | C7: Germany | D7: Government | E7: Carretera | F7: 1513 | G7: 0 | H7: =DATE(K7,J7,I7) -> 41974 | I7: 1 | J7: 12 | K7: 2014 | L7: =VLOOKUP(E7,Product!$A$1:$C$7,3,0)*'Order Raw'!F7 -> 30260 | M7: =L7-G7 -> 30260 | N7: =M7-(VLOOKUP(E7,Product!$A$1:$C$7,2,0)*F7) -> 25721 | Q7: Yearly | R7: =_xlfn.FORMULATEXT(U3) -> =SUMIFS(SalesTable[Gross Profit];SalesTable[Year];Q3) | S7: 2014
A8: {"type": "buyerDetails", "info": ["origin": "Germany", "segment": "Midmarket", "date": "1", "month": "3", "year": "2014", "units": "921"]} | B8: =_xlfn.IFS(C8="Canada","CND",C8="Germany","GER",C8="France","FRA",C8="Mexico","MXC",C8="United States of America","USA")&"-"&_xlfn.IFS(D8="Government","GOV",D8="Midmarket","MDM",D8="Channel Partners","CPR",D8="Enterprise","ENT",D8="Small Business","SMB")&"-"&TEXT(H8,"yyyymmdd") -> GER-MDM-20140301 | C8: Germany | D8: Midmarket | E8: Montana | F8: 921 | G8: 0 | H8: =DATE(K8,J8,I8) -> 41699 | I8: 1 | J8: 3 | K8: 2014 | L8: =VLOOKUP(E8,Product!$A$1:$C$7,3,0)*'Order Raw'!F8 -> 13815 | M8: =L8-G8 -> 13815 | N8: =M8-(VLOOKUP(E8,Product!$A$1:$C$7,2,0)*F8) -> 9210
A9: {"type": "buyerDetails", "info": ["origin": "Canada", "segment": "Channel Partners", "date": "1", "month": "6", "year": "2014", "units": "2518"]} | B9: =_xlfn.IFS(C9="Canada","CND",C9="Germany","GER",C9="France","FRA",C9="Mexico","MXC",C9="United States of America","USA")&"-"&_xlfn.IFS(D9="Government","GOV",D9="Midmarket","MDM",D9="Channel Partners","CPR",D9="Enterprise","ENT",D9="Small Business","SMB")&"-"&TEXT(H9,"yyyymmdd") -> CND-CPR-20140601 | C9: Canada | D9: Channel Partners | E9: Montana | F9: 2518 | G9: 0 | H9: =DATE(K9,J9,I9) -> 41791 | I9: 1 | J9: 6 | K9: 2014 | L9: =VLOOKUP(E9,Product!$A$1:$C$7,3,0)*'Order Raw'!F9 -> 37770 | M9: =L9-G9 -> 37770 | N9: =M9-(VLOOKUP(E9,Product!$A$1:$C$7,2,0)*F9) -> 25180 | Q9: per order | R9: =_xlfn.FORMULATEXT(N2) -> =M2-(VLOOKUP(E2;Product!$A$1:$C$7;2;0)*F2)
A10: {"type": "buyerDetails", "info": ["origin": "France", "segment": "Government", "date": "1", "month": "6", "year": "2014", "units": "1899"]} | B10: =_xlfn.IFS(C10="Canada","CND",C10="Germany","GER",C10="France","FRA",C10="Mexico","MXC",C10="United States of America","USA")&"-"&_xlfn.IFS(D10="Government","GOV",D10="Midmarket","MDM",D10="Channel Partners","CPR",D10="Enterprise","ENT",D10="Small Business","SMB")&"-"&TEXT(H10,"yyyymmdd") -> FRA-GOV-20140601 | C10: France | D10: Government | E10: Montana | F10: 1899 | G10: 0 | H10: =DATE(K10,J10,I10) -> 41791 | I10: 1 | J10: 6 | K10: 2014 | L10: =VLOOKUP(E10,Product!$A$1:$C$7,3,0)*'Order Raw'!F10 -> 28485 | M10: =L10-G10 -> 28485 | N10: =M10-(VLOOKUP(E10,Product!$A$1:$C$7,2,0)*F10) -> 18990
A11: {"type": "buyerDetails", "info": ["origin": "Germany", "segment": "Channel Partners", "date": "1", "month": "6", "year": "2014", "units": "1545"]} | B11: =_xlfn.IFS(C11="Canada","CND",C11="Germany","GER",C11="France","FRA",C11="Mexico","MXC",C11="United States of America","USA")&"-"&_xlfn.IFS(D11="Government","GOV",D11="Midmarket","MDM",D11="Channel Partners","CPR",D11="Enterprise","ENT",D11="Small Business","SMB")&"-"&TEXT(H11,"yyyymmdd") -> GER-CPR-20140601 | C11: Germany | D11: Channel Partners | E11: Montana | F11: 1545 | G11: 0 | H11: =DATE(K11,J11,I11) -> 41791 | I11: 1 | J11: 6 | K11: 2014 | L11: =VLOOKUP(E11,Product!$A$1:$C$7,3,0)*'Order Raw'!F11 -> 23175 | M11: =L11-G11 -> 23175 | N11: =M11-(VLOOKUP(E11,Product!$A$1:$C$7,2,0)*F11) -> 15450
A12: {"type": "buyerDetails", "info": ["origin": "Mexico", "segment": "Midmarket", "date": "1", "month": "6", "year": "2014", "units": "2470"]} | B12: =_xlfn.IFS(C12="Canada","CND",C12="Germany","GER",C12="France","FRA",C12="Mexico","MXC",C12="United States of America","USA")&"-"&_xlfn.IFS(D12="Government","GOV",D12="Midmarket","MDM",D12="Channel Partners","CPR",D12="Enterprise","ENT",D12="Small Business","SMB")&"-"&TEXT(H12,"yyyymmdd") -> MXC-MDM-20140601 | C12: Mexico | D12: Midmarket | E12: Montana | F12: 2470 | G12: 0 | H12: =DATE(K12,J12,I12) -> 41791 | I12: 1 | J12: 6 | K12: 2014 | L12: =VLOOKUP(E12,Product!$A$1:$C$7,3,0)*'Order Raw'!F12 -> 37050 | M12: =L12-G12 -> 37050 | N12: =M12-(VLOOKUP(E12,Product!$A$1:$C$7,2,0)*F12) -> 24700
A13: {"type": "buyerDetails", "info": ["origin": "Canada", "segment": "Enterprise", "date": "1", "month": "7", "year": "2014", "units": "2665"]} | B13: =_xlfn.IFS(C13="Canada","CND",C13="Germany","GER",C13="France","FRA",C13="Mexico","MXC",C13="United States of America","USA")&"-"&_xlfn.IFS(D13="Government","GOV",D13="Midmarket","MDM",D13="Channel Partners","CPR",D13="Enterprise","ENT",D13="Small Business","SMB")&"-"&TEXT(H13,"yyyymmdd") -> CND-ENT-20140701 | C13: Canada | D13: Enterprise | E13: Montana | F13: 2665 | G13: 0 | H13: =DATE(K13,J13,I13) -> 41821 | I13: 1 | J13: 7 | K13: 2014 | L13: =VLOOKUP(E13,Product!$A$1:$C$7,3,0)*'Order Raw'!F13 -> 39975 | M13: =L13-G13 -> 39975 | N13: =M13-(VLOOKUP(E13,Product!$A$1:$C$7,2,0)*F13) -> 26650
A14: {"type": "buyerDetails", "info": ["origin": "Mexico", "segment": "Small Business", "date": "1", "month": "8", "year": "2014", "units": "958"]} | B14: =_xlfn.IFS(C14="Canada","CND",C14="Germany","GER",C14="France","FRA",C14="Mexico","MXC",C14="United States of America","USA")&"-"&_xlfn.IFS(D14="Government","GOV",D14="Midmarket","MDM",D14="Channel Partners","CPR",D14="Enterprise","ENT",D14="Small Business","SMB")&"-"&TEXT(H14,"yyyymmdd") -> MXC-SMB-20140801 | C14: Mexico | D14: Small Business | E14: Montana | F14: 958 | G14: 0 | H14: =DATE(K14,J14,I14) -> 41852 | I14: 1 | J14: 8 | K14: 2014 | L14: =VLOOKUP(E14,Product!$A$1:$C$7,3,0)*'Order Raw'!F14 -> 14370 | M14: =L14-G14 -> 14370 | N14: =M14-(VLOOKUP(E14,Product!$A$1:$C$7,2,0)*F14) -> 9580
A15: {"type": "buyerDetails", "info": ["origin": "Germany", "segment": "Government", "date": "1", "month": "9", "year": "2014", "units": "2146"]} | B15: =_xlfn.IFS(C15="Canada","CND",C15="Germany","GER",C15="France","FRA",C15="Mexico","MXC",C15="United States of America","USA")&"-"&_xlfn.IFS(D15="Government","GOV",D15="Midmarket","MDM",D15="Channel Partners","CPR",D15="Enterprise","ENT",D15="Small Business","SMB")&"-"&TEXT(H15,"yyyymmdd") -> GER-GOV-20140901 | C15: Germany | D15: Government | E15: Montana | F15: 2146 | G15: 0 | H15: =DATE(K15,J15,I15) -> 41883 | I15: 1 | J15: 9 | K15: 2014 | L15: =VLOOKUP(E15,Product!$A$1:$C$7,3,0)*'Order Raw'!F15 -> 32190 | M15: =L15-G15 -> 32190 | N15: =M15-(VLOOKUP(E15,Product!$A$1:$C$7,2,0)*F15) -> 21460
A16: {"type": "buyerDetails", "info": ["origin": "Canada", "segment": "Enterprise", "date": "1", "month": "10", "year": "2013", "units": "345"]} | B16: =_xlfn.IFS(C16="Canada","CND",C16="Germany","GER",C16="France","FRA",C16="Mexico","MXC",C16="United States of America","USA")&"-"&_xlfn.IFS(D16="Government","GOV",D16="Midmarket","MDM",D16="Channel Partners","CPR",D16="Enterprise","ENT",D16="Small Business","SMB")&"-"&TEXT(H16,"yyyymmdd") -> CND-ENT-20131001 | C16: Canada | D16: Enterprise | E16: Montana | F16: 345 | G16: 0 | H16: =DATE(K16,J16,I16) -> 41548 | I16: 1 | J16: 10 | K16: 2013 | L16: =VLOOKUP(E16,Product!$A$1:$C$7,3,0)*'Order Raw'!F16 -> 5175 | M16: =L16-G16 -> 5175 | N16: =M16-(VLOOKUP(E16,Product!$A$1:$C$7,2,0)*F16) -> 3450
A17: {"type": "buyerDetails", "info": ["origin": "United States of America", "segment": "Midmarket", "date": "1", "month": "12", "year": "2014", "units": "615"]} | B17: =_xlfn.IFS(C17="Canada","CND",C17="Germany","GER",C17="France","FRA",C17="Mexico","MXC",C17="United States of America","USA")&"-"&_xlfn.IFS(D17="Government","GOV",D17="Midmarket","MDM",D17="Channel Partners","CPR",D17="Enterprise","ENT",D17="Small Business","SMB")&"-"&TEXT(H17,"yyyymmdd") -> USA-MDM-20141201 | C17: United States of America | D17: Midmarket | E17: Montana | F17: 615 | G17: 0 | H17: =DATE(K17,J17,I17) -> 41974 | I17: 1 | J17: 12 | K17: 2014 | L17: =VLOOKUP(E17,Product!$A$1:$C$7,3,0)*'Order Raw'!F17 -> 9225 | M17: =L17-G17 -> 9225 | N17: =M17-(VLOOKUP(E17,Product!$A$1:$C$7,2,0)*F17) -> 6150
A18: {"type": "buyerDetails", "info": ["origin": "Canada", "segment": "Government", "date": "1", "month": "2", "year": "2014", "units": "292"]} | B18: =_xlfn.IFS(C18="Canada","CND",C18="Germany","GER",C18="France","FRA",C18="Mexico","MXC",C18="United States of America","USA")&"-"&_xlfn.IFS(D18="Government","GOV",D18="Midmarket","MDM",D18="Channel Partners","CPR",D18="Enterprise","ENT",D18="Small Business","SMB")&"-"&TEXT(H18,"yyyymmdd") -> CND-GOV-20140201 | C18: Canada | D18: Government | E18: Paseo | F18: 292 | G18: 0 | H18: =DATE(K18,J18,I18) -> 41671 | I18: 1 | J18: 2 | K18: 2014 | L18: =VLOOKUP(E18,Product!$A$1:$C$7,3,0)*'Order Raw'!F18 -> 5840 | M18: =L18-G18 -> 5840 | N18: =M18-(VLOOKUP(E18,Product!$A$1:$C$7,2,0)*F18) -> 2920
A19: {"type": "buyerDetails", "info": ["origin": "Mexico", "segment": "Midmarket", "date": "1", "month": "2", "year": "2014", "units": "974"]} | B19: =_xlfn.IFS(C19="Canada","CND",C19="Germany","GER",C19="France","FRA",C19="Mexico","MXC",C19="United States of America","USA")&"-"&_xlfn.IFS(D19="Government","GOV",D19="Midmarket","MDM",D19="Channel Partners","CPR",D19="Enterprise","ENT",D19="Small Business","SMB")&"-"&TEXT(H19,"yyyymmdd") -> MXC-MDM-20140201 | C19: Mexico | D19: Midmarket | E19: Paseo | F19: 974 | G19: 0 | H19: =DATE(K19,J19,I19) -> 41671 | I19: 1 | J19: 2 | K19: 2014 | L19: =VLOOKUP(E19,Product!$A$1:$C$7,3,0)*'Order Raw'!F19 -> 19480 | M19: =L19-G19 -> 19480 | N19: =M19-(VLOOKUP(E19,Product!$A$1:$C$7,2,0)*F19) -> 9740
A20: {"type": "buyerDetails", "info": ["origin": "Canada", "segment": "Channel Partners", "date": "1", "month": "6", "year": "2014", "units": "2518"]} | B20: =_xlfn.IFS(C20="Canada","CND",C20="Germany","GER",C20="France","FRA",C20="Mexico","MXC",C20="United States of America","USA")&"-"&_xlfn.IFS(D20="Government","GOV",D20="Midmarket","MDM",D20="Channel Partners","CPR",D20="Enterprise","ENT",D20="Small Business","SMB")&"-"&TEXT(H20,"yyyymmdd") -> CND-CPR-20140601 | C20: Canada | D20: Channel Partners | E20: Paseo | F20: 2518 | G20: 0 | H20: =DATE(K20,J20,I20) -> 41791 | I20: 1 | J20: 6 | K20: 2014 | L20: =VLOOKUP(E20,Product!$A$1:$C$7,3,0)*'Order Raw'!F20 -> 50360 | M20: =L20-G20 -> 50360 | N20: =M20-(VLOOKUP(E20,Product!$A$1:$C$7,2,0)*F20) -> 25180
A21: {"type": "buyerDetails", "info": ["origin": "Germany", "segment": "Government", "date": "1", "month": "6", "year": "2014", "units": "1006"]} | B21: =_xlfn.IFS(C21="Canada","CND",C21="Germany","GER",C21="France","FRA",C21="Mexico","MXC",C21="United States of America","USA")&"-"&_xlfn.IFS(D21="Government","GOV",D21="Midmarket","MDM",D21="Channel Partners","CPR",D21="Enterprise","ENT",D21="Small Business","SMB")&"-"&TEXT(H21,"yyyymmdd") -> GER-GOV-20140601 | C21: Germany | D21: Government | E21: Paseo | F21: 1006 | G21: 0 | H21: =DATE(K21,J21,I21) -> 41791 | I21: 1 | J21: 6 | K21: 2014 | L21: =VLOOKUP(E21,Product!$A$1:$C$7,3,0)*'Order Raw'!F21 -> 20120 | M21: =L21-G21 -> 20120 | N21: =M21-(VLOOKUP(E21,Product!$A$1:$C$7,2,0)*F21) -> 10060
... A701: {"type": "buyerDetails", "info": ["origin": "United States of America", "segment": "Channel Partners", "date": "1", "month": "5", "year": "2014", "units": "1806"]} | B701: =_xlfn.IFS(C701="Canada","CND",C701="Germany","GER",C701="France","FRA",C701="Mexico","MXC",C701="United States of America","USA")&"-"&_xlfn.IFS(D701="Government","GOV",D701="Midmarket","MDM",D701="Channel Partners","CPR",D701="Enterprise","ENT",D701="Small Business","SMB")&"-"&TEXT(H701,"yyyymmdd") -> USA-CPR-20140501 | C701: United States of America | D701: Channel Partners | E701: VTT | F701: 1806 | G701: 0.15 | H701: =DATE(K701,J701,I701) -> 41760 | I701: 1 | J701: 5 | K701: 2014 | L701: =VLOOKUP(E701,Product!$A$1:$C$7,3,0)*'Order Raw'!F701 -> 541800 | M701: =L701-G701 -> 541799.85 | N701: =M701-(VLOOKUP(E701,Product!$A$1:$C$7,2,0)*F701) -> 90299.85

Sheet Product
A1: Product | B1: Manufacturing cost | C1: Selling price
A2: Carretera | B2: 3 | C2: 20
A3: Montana | B3: 5 | C3: 15
A4: Paseo | B4: 10 | C4: 20
A5: Velo | B5: 120 | C5: 180
A6: VTT | B6: 250 | C6: 300
A7: Amarilla | B7: 200 | C7: 350

Sheet Discount
A1: Discount type | B1: Discount range
A2: Low | B2: 1% - 4%
A3: Medium | B3: 5% - 9%
A4: High | B4: 10% - 15%

Sheet Other financials
A1: Name | B1: Definition | C1: Value | D1: Year | F1: Year | G1: Gross Profit | H1: Operating Profit | I1: Net Profit
A2: G&A Cost | B2: General expenses & administrative expenses | C2: 854023 | D2: 2013 | F2: 2013 | G2: =SUMIFS(#REF!,#REF!,'Other financials'!F2) -> #REF! | H2: =G2-C2-C3 -> #REF! | I2: =H2-C4 -> #REF!
A3: Handling cost | B3: Cost for handling orders | C3: 2895322 | D3: 2013 | F3: 2014 | G3: =SUMIFS(#REF!,#REF!,'Other financials'!F3) -> #REF! | H3: =G3-C5-C6 -> #REF! | I3: =H3-C7 -> #REF!
A4: Tax | B4: Taxes charged to the company | C4: 1037476 | D4: 2013 | F4: 2015
A5: G&A Cost | B5: General expenses & administrative expenses | C5: 3532853 | D5: 2014
A6: Handling cost | B6: Cost for handling orders | C6: 9213451 | D6: 2014 | F6: Row Labels | G6: Sum of Gross Profit | H6: Sum of Operating Profit | I6: Sum of Net Profit
A7: Tax | B7: Taxes charged to the company | C7: 3659693 | D7: 2014 | F7: 2013 | G7: #REF! | H7: #REF! | I7: #REF!
A8: Revenue | B8: Projected revenue | C8: 39582132 | D8: 2015 | F8: 2014 | G8: #REF! | H8: #REF! | I8: #REF!
A9: Net Profit | B9: Projected net profit | C9: 16652123 | D9: 2015 | F9: Grand Total | G9: #REF! | H9: #REF! | I9: #REF!
